Traceback (most recent call last):
  File "/home/pewhite/github/aet-cs/aet-cs.github.io/white/ML/env/lib/python3.11/site-packages/jupyter_cache/executors/utils.py", line 58, in single_nb_execution
    executenb(
  File "/home/pewhite/github/aet-cs/aet-cs.github.io/white/ML/env/lib/python3.11/site-packages/nbclient/client.py", line 1314, in execute
    return NotebookClient(nb=nb, resources=resources, km=km, **kwargs).execute()
           ^^^^^^^^^^^^^^^^^^^^^^^^^^^^^^^^^^^^^^^^^^^^^^^^^^^^^^^^^^^^^^^^^^^^^
  File "/home/pewhite/github/aet-cs/aet-cs.github.io/white/ML/env/lib/python3.11/site-packages/jupyter_core/utils/__init__.py", line 165, in wrapped
    return loop.run_until_complete(inner)
           ^^^^^^^^^^^^^^^^^^^^^^^^^^^^^^
  File "/home/pewhite/.asdf/installs/python/3.11.9/lib/python3.11/asyncio/base_events.py", line 654, in run_until_complete
    return future.result()
           ^^^^^^^^^^^^^^^
  File "/home/pewhite/github/aet-cs/aet-cs.github.io/white/ML/env/lib/python3.11/site-packages/nbclient/client.py", line 709, in async_execute
    await self.async_execute_cell(
  File "/home/pewhite/github/aet-cs/aet-cs.github.io/white/ML/env/lib/python3.11/site-packages/nbclient/client.py", line 1062, in async_execute_cell
    await self._check_raise_for_error(cell, cell_index, exec_reply)
  File "/home/pewhite/github/aet-cs/aet-cs.github.io/white/ML/env/lib/python3.11/site-packages/nbclient/client.py", line 918, in _check_raise_for_error
    raise CellExecutionError.from_cell_and_msg(cell, exec_reply_content)
nbclient.exceptions.CellExecutionError: An error occurred while executing the following cell:
------------------
x = np.arange(3,5,0.01)
y = 0.25*3**x

# add noise, but keep y > 0
for i in range(len(y)):
    while True:
        noise  = random.gauss(0,y[i]/10)
        if (y[i]+noise > 0):
            break
    y[i] += noise

plt.scatter(x,y,s=0.5);
plt.title("Exponential correlation");
------------------


[0;31m---------------------------------------------------------------------------[0m
[0;31mNameError[0m                                 Traceback (most recent call last)
Cell [0;32mIn[4], line 7[0m
[1;32m      5[0m [38;5;28;01mfor[39;00m i [38;5;129;01min[39;00m [38;5;28mrange[39m([38;5;28mlen[39m(y)):
[1;32m      6[0m     [38;5;28;01mwhile[39;00m [38;5;28;01mTrue[39;00m:
[0;32m----> 7[0m         noise  [38;5;241m=[39m [43mrandom[49m[38;5;241m.[39mgauss([38;5;241m0[39m,y[i][38;5;241m/[39m[38;5;241m10[39m)
[1;32m      8[0m         [38;5;28;01mif[39;00m (y[i][38;5;241m+[39mnoise [38;5;241m>[39m [38;5;241m0[39m):
[1;32m      9[0m             [38;5;28;01mbreak[39;00m

[0;31mNameError[0m: name 'random' is not defined

