Traceback (most recent call last):
  File "/home/pewhite/github/aet-cs/aet-cs.github.io/white/ML/env/lib/python3.11/site-packages/jupyter_cache/executors/utils.py", line 58, in single_nb_execution
    executenb(
  File "/home/pewhite/github/aet-cs/aet-cs.github.io/white/ML/env/lib/python3.11/site-packages/nbclient/client.py", line 1314, in execute
    return NotebookClient(nb=nb, resources=resources, km=km, **kwargs).execute()
           ^^^^^^^^^^^^^^^^^^^^^^^^^^^^^^^^^^^^^^^^^^^^^^^^^^^^^^^^^^^^^^^^^^^^^
  File "/home/pewhite/github/aet-cs/aet-cs.github.io/white/ML/env/lib/python3.11/site-packages/jupyter_core/utils/__init__.py", line 165, in wrapped
    return loop.run_until_complete(inner)
           ^^^^^^^^^^^^^^^^^^^^^^^^^^^^^^
  File "/home/pewhite/.asdf/installs/python/3.11.9/lib/python3.11/asyncio/base_events.py", line 654, in run_until_complete
    return future.result()
           ^^^^^^^^^^^^^^^
  File "/home/pewhite/github/aet-cs/aet-cs.github.io/white/ML/env/lib/python3.11/site-packages/nbclient/client.py", line 709, in async_execute
    await self.async_execute_cell(
  File "/home/pewhite/github/aet-cs/aet-cs.github.io/white/ML/env/lib/python3.11/site-packages/nbclient/client.py", line 1062, in async_execute_cell
    await self._check_raise_for_error(cell, cell_index, exec_reply)
  File "/home/pewhite/github/aet-cs/aet-cs.github.io/white/ML/env/lib/python3.11/site-packages/nbclient/client.py", line 918, in _check_raise_for_error
    raise CellExecutionError.from_cell_and_msg(cell, exec_reply_content)
nbclient.exceptions.CellExecutionError: An error occurred while executing the following cell:
------------------
features = df.select_dtypes(include=['number']).columns  # Select numerical columns if needed
X = df[features]

# Standardize the features
scaler = StandardScaler()
X_scaled = scaler.fit_transform(X)

# Perform PCA
num_components = 100
pca = PCA(n_components=num_components)  
X_pca = pca.fit_transform(X_scaled)

X_train, X_test, y_train, y_test = train_test_split(X_pca, y, test_size=0.2, random_state=42)

linreg = LinearRegression()
model = linreg.fit(X_train, y_train)
print("Score = ", linreg.score(X_test, y_test))
------------------


[0;31m---------------------------------------------------------------------------[0m
[0;31mNameError[0m                                 Traceback (most recent call last)
Cell [0;32mIn[9], line 15[0m
[1;32m     11[0m X_pca [38;5;241m=[39m pca[38;5;241m.[39mfit_transform(X_scaled)
[1;32m     13[0m X_train, X_test, y_train, y_test [38;5;241m=[39m train_test_split(X_pca, y, test_size[38;5;241m=[39m[38;5;241m0.2[39m, random_state[38;5;241m=[39m[38;5;241m42[39m)
[0;32m---> 15[0m linreg [38;5;241m=[39m [43mLinearRegression[49m()
[1;32m     16[0m model [38;5;241m=[39m linreg[38;5;241m.[39mfit(X_train, y_train)
[1;32m     17[0m [38;5;28mprint[39m([38;5;124m"[39m[38;5;124mScore = [39m[38;5;124m"[39m, linreg[38;5;241m.[39mscore(X_test, y_test))

[0;31mNameError[0m: name 'LinearRegression' is not defined

